// For good measure let's catch everything we can, just in case.
process
  .on('unhandledRejection', (reason, p) => {
    console.error(reason, 'Unhandled Rejection at Promise', p);
  })
  .on('uncaughtException', err => {
    console.error(err, 'Uncaught Exception thrown');
    process.exit(1);
  });